Workbook

Sheet Plastics CCUS_COMPARISON
I1: HDPE DEMAND 2024 | J1: =J12*1.4/100*1.055 -> 302.27344 | M1: RMTO | N1: RMTP | O1: ROCM | S1: RMTO | T1: RMTP | U1: ROCM | W1: Natural gas thousand cu ft/car | X1: Natural gas Million (m3)/car | Y1: Crude oil gal/car | Z1: Crude oil Thousands (m3)/car | AA1: Electricity kWh/car | AC1: ng mass
E2: Value/car | I2: 14.168411 | J2: 13.236279 | K2: 19.947632 | L2: 1.3049853 | M2: 1.3049853 | P2: 2.6099705 | R2: 2.6099705 | S2: 2.6099705 | V2: 2.0506911 | W2: 13.049853 | X2: 6.5249263 | Y2: 3.1692499 | Z2: 33.74319 | AA2: 22.744029 | AB2: 21.62547 | AC2: 25.726852 | AE2: 7.4623924 | AF2: =28.32*7.46239236299982 -> 211.33495 | AG2: 22.472903 | AH2: =0.00378541*22.4729025711425 -> 0.08506915 | AI2: 356.27222 | AK2: 2636.4 | AL2: 50000
A3: ='Texas pop'!A99 -> Year | B3: ='Texas pop'!B99 -> Population | C3: ='Texas pop'!C99 -> EVs | D3: ='Texas pop'!D99 -> EVs w retirement | E3: ='Texas pop'!E99 -> Sales Difference/New cars | F3: ENERGY REQUIRED [PJ] | G3: TONS OF CO2 EMITTED | H3: TONS OF CO2 CAPTURED | I3: TONS OF PE PRODUCED THROGH CCUS | J3: TONS REQ | K3: DELTA (NG NEEDED) | L3: FINAL PRICE/ TON PLASTIC CONVENTIONAL | M3: FINAL PRICE/ TON PLASTIC NO EMISSIONS | N3: FINAL PRICE/ TON PLASTIC NO EMISSIONS | O3: FINAL PRICE/ TON PLASTIC NO EMISSIONS | P3: JANUARY NG PRICE BASED (USD/THOUSAND CU FT) | Q3: NG PRICE/TON PLASTIC | R3: CCUS PRICE | S3: RATIO COST NO EMI/EM | V3: ABS | W3: EPDM | X3: LER | Y3: GPPS | Z3: HIPS | AA3: HDPE | AB3: LDPE | AC3: LLDPE | AD3: Nylon 6 | AE3: Nylon 66 | AF3: PC | AG3: PET | AH3: PP | AI3: FPUR foam | AJ3: RPUR foam | AK3: PVC | AL3: Total | AM3: NG | AN3: NG | AO3: Crude oil | AQ3: Electricity | AS3: =AT3*AK2/AL2 -> 393.47702 | AT3: =7.46239236299982*1000 -> 7462.3924
A4: ='Texas pop'!A100 -> 2016 | B4: ='Texas pop'!B100 -> 27914064 | C4: ='Texas pop'!C100 -> 11900 | D4: ='Texas pop'!D100 -> 11900 | E4: ='Texas pop'!E100 -> 4200 | F4: =E4*$C$46*$D$45/1000000000 -> 0.058361977 | G4: =E4/1000*$D$41/0.9/1000 -> 2.4208779 | H4: 0 | I4: =H4/$D$42*$D$43 -> 0 | J4: =$D$45*E4/1000 -> 808.626 | L4: =Q4 -> 453.7037 | M4: ='Plastics CCUS_RMTO'!M4 -> 453.7037 | N4: ='Plastics CCUS_RMTP'!M4 -> 453.7037 | O4: ='Plastics CCUS_ROCM'!M4 -> 453.7037 | P4: 2.45 | Q4: =$H$50/2.7*P4 -> 453.7037 | R4: =R5/D43 -> 1955.1356 | S4: ='Plastics CCUS_RMTO'!Q4 -> 1 | T4: ='Plastics CCUS_RMTP'!Q4 -> 1 | U4: ='Plastics CCUS_ROCM'!Q4 -> 1 | V4: =$E4*I$2/1000000 -> 0.059507328 | W4: =$E4*J$2/1000000 -> 0.055592372 | X4: =$E4*K$2/1000000 -> 0.083780053 | Y4: =$E4*L$2/1000000 -> 0.0054809381 | Z4: =$E4*M$2/1000000 -> 0.0054809381 | AA4: =$E4*P$2/1000000 -> 0.010961876 | AB4: =$E4*R$2/1000000 -> 0.010961876 | AC4: =$E4*S$2/1000000 -> 0.010961876 | AD4: =$E4*V$2/1000000 -> 0.0086129027 | AE4: =$E4*W$2/1000000 -> 0.054809381 | AF4: =$E4*X$2/1000000 -> 0.02740469 | AG4: =$E4*Y$2/1000000 -> 0.01331085 | AH4: =$E4*Z$2/1000000 -> 0.1417214 | AI4: =$E4*AA$2/1000000 -> 0.095524921 | AJ4: =$E4*AB$2/1000000 -> 0.090826974 | AK4: =$E4*AC$2/1000000 -> 0.10805278 | AL4: =SUM(V4:AK4) -> 0.78299115 | AM4: =$E4*AE$2 -> 31342.048 | AN4: =$E4*AF$2/1000000 -> 0.8876068 | AO4: =$E4*AG$2/(42*1000) -> 2.2472903 | AP4: =$E4*AH$2/1000 -> 0.35729043 | AQ4: =$E4*AI$2/1000000 -> 1.4963433 | AS4: =AS3*AT5 -> 178.47803 | AT4: kgs
A5: ='Texas pop'!A101 -> 2017 | B5: ='Texas pop'!B101 -> 28291024 | C5: ='Texas pop'!C101 -> 16100 | D5: ='Texas pop'!D101 -> 16100 | E5: ='Texas pop'!E101 -> 8400 | F5: =E5*$C$46*$D$45/1000000000 -> 0.11672395 | G5: =E5/1000*$D$41/0.9/1000 -> 4.8417558 | H5: 0 | I5: =H5/$D$42*$D$43 -> 0 | J5: =$D$45*E5/1000 -> 1617.252 | K5: =J5-I4 -> 1617.252 | L5: =Q5 -> 711.11111 | M5: ='Plastics CCUS_RMTO'!M5 -> 711.11111 | N5: ='Plastics CCUS_RMTP'!M5 -> 711.11111 | O5: ='Plastics CCUS_ROCM'!M5 -> 711.11111 | P5: 3.84 | Q5: =$H$50/2.7*P5 -> 711.11111 | R5: =D50/D43 -> 1857.3788 | S5: ='Plastics CCUS_RMTO'!Q5 -> 1 | T5: ='Plastics CCUS_RMTP'!Q5 -> 1 | U5: ='Plastics CCUS_ROCM'!Q5 -> 1 | V5: =$E5*I$2/1000000 -> 0.11901466 | W5: =$E5*J$2/1000000 -> 0.11118474 | X5: =$E5*K$2/1000000 -> 0.16756011 | Y5: =$E5*L$2/1000000 -> 0.010961876 | Z5: =$E5*M$2/1000000 -> 0.010961876 | AA5: =$E5*P$2/1000000 -> 0.021923752 | AB5: =$E5*R$2/1000000 -> 0.021923752 | AC5: =$E5*S$2/1000000 -> 0.021923752 | AD5: =$E5*V$2/1000000 -> 0.017225805 | AE5: =$E5*W$2/1000000 -> 0.10961876 | AF5: =$E5*X$2/1000000 -> 0.054809381 | AG5: =$E5*Y$2/1000000 -> 0.026621699 | AH5: =$E5*Z$2/1000000 -> 0.2834428 | AI5: =$E5*AA$2/1000000 -> 0.19104984 | AJ5: =$E5*AB$2/1000000 -> 0.18165395 | AK5: =$E5*AC$2/1000000 -> 0.21610556 | AL5: =SUM(V5:AK5) -> 1.5659823 | AM5: =$E5*AE$2 -> 62684.096 | AN5: =$E5*AF$2/1000000 -> 1.7752136 | AO5: =$E5*AG$2/(42*1000) -> 4.4945805 | AP5: =$E5*AH$2/1000 -> 0.71458086 | AQ5: =$E5*AI$2/1000000 -> 2.9926866 | AS5: lbs to kg | AT5: 0.453592
A6: ='Texas pop'!A102 -> 2018 | B6: ='Texas pop'!B102 -> 28624564 | C6: ='Texas pop'!C102 -> 24500 | D6: ='Texas pop'!D102 -> 24500 | E6: ='Texas pop'!E102 -> 13900 | F6: =E6*$C$46*$D$45/1000000000 -> 0.19315035 | G6: =E6/1000*$D$41/0.9/1000 -> 8.0119531 | H6: 0 | I6: =H6/$D$42*$D$43 -> 0 | J6: =$D$45*E6/1000 -> 2676.167 | K6: =J6-I5 -> 2676.167 | L6: =Q6 -> 620.37037 | M6: ='Plastics CCUS_RMTO'!M6 -> 620.37037 | N6: ='Plastics CCUS_RMTP'!M6 -> 620.37037 | O6: ='Plastics CCUS_ROCM'!M6 -> 620.37037 | P6: 3.35 | Q6: =$H$50/2.7*P6 -> 620.37037 | R6: =R5*(1-0.01) -> 1838.805 | S6: ='Plastics CCUS_RMTO'!Q6 -> 1 | T6: ='Plastics CCUS_RMTP'!Q6 -> 1 | U6: ='Plastics CCUS_ROCM'!Q6 -> 1 | V6: =$E6*I$2/1000000 -> 0.19694092 | W6: =$E6*J$2/1000000 -> 0.18398428 | X6: =$E6*K$2/1000000 -> 0.27727208 | Y6: =$E6*L$2/1000000 -> 0.018139295 | Z6: =$E6*M$2/1000000 -> 0.018139295 | AA6: =$E6*P$2/1000000 -> 0.03627859 | AB6: =$E6*R$2/1000000 -> 0.03627859 | AC6: =$E6*S$2/1000000 -> 0.03627859 | AD6: =$E6*V$2/1000000 -> 0.028504607 | AE6: =$E6*W$2/1000000 -> 0.18139295 | AF6: =$E6*X$2/1000000 -> 0.090696475 | AG6: =$E6*Y$2/1000000 -> 0.044052574 | AH6: =$E6*Z$2/1000000 -> 0.46903034 | AI6: =$E6*AA$2/1000000 -> 0.316142 | AJ6: =$E6*AB$2/1000000 -> 0.30059403 | AK6: =$E6*AC$2/1000000 -> 0.35760325 | AL6: =SUM(V6:AK6) -> 2.5913279 | AM6: =$E6*AE$2 -> 103727.25 | AN6: =$E6*AF$2/1000000 -> 2.9375558 | AO6: =$E6*AG$2/(42*1000) -> 7.4374606 | AP6: =$E6*AH$2/1000 -> 1.1824612 | AQ6: =$E6*AI$2/1000000 -> 4.9521838
A7: ='Texas pop'!A103 -> 2019 | B7: ='Texas pop'!B103 -> 28986794 | C7: ='Texas pop'!C103 -> 38400 | D7: ='Texas pop'!D103 -> 38400 | E7: ='Texas pop'!E103 -> 13800 | F7: =E7*$C$46*$D$45/1000000000 -> 0.19176078 | G7: =E7/1000*$D$41/0.9/1000 -> 7.9543131 | H7: 0 | I7: =H7/$D$42*$D$43 -> 0 | J7: =$D$45*E7/1000 -> 2656.914 | K7: =J7-I6 -> 2656.914 | L7: =Q7 -> 725.92593 | M7: ='Plastics CCUS_RMTO'!M7 -> 725.92593 | N7: ='Plastics CCUS_RMTP'!M7 -> 725.92593 | O7: ='Plastics CCUS_ROCM'!M7 -> 725.92593 | P7: 3.92 | Q7: =$H$50/2.7*P7 -> 725.92593 | R7: =R6*(1-0.01) -> 1820.417 | S7: ='Plastics CCUS_RMTO'!Q7 -> 1 | T7: ='Plastics CCUS_RMTP'!Q7 -> 1 | U7: ='Plastics CCUS_ROCM'!Q7 -> 1 | V7: =$E7*I$2/1000000 -> 0.19552408 | W7: =$E7*J$2/1000000 -> 0.18266065 | X7: =$E7*K$2/1000000 -> 0.27527732 | Y7: =$E7*L$2/1000000 -> 0.018008797 | Z7: =$E7*M$2/1000000 -> 0.018008797 | AA7: =$E7*P$2/1000000 -> 0.036017593 | AB7: =$E7*R$2/1000000 -> 0.036017593 | AC7: =$E7*S$2/1000000 -> 0.036017593 | AD7: =$E7*V$2/1000000 -> 0.028299537 | AE7: =$E7*W$2/1000000 -> 0.18008797 | AF7: =$E7*X$2/1000000 -> 0.090043983 | AG7: =$E7*Y$2/1000000 -> 0.043735649 | AH7: =$E7*Z$2/1000000 -> 0.46565602 | AI7: =$E7*AA$2/1000000 -> 0.3138676 | AJ7: =$E7*AB$2/1000000 -> 0.29843149 | AK7: =$E7*AC$2/1000000 -> 0.35503056 | AL7: =SUM(V7:AK7) -> 2.5726852 | AM7: =$E7*AE$2 -> 102981.01 | AN7: =$E7*AF$2/1000000 -> 2.9164223 | AO7: =$E7*AG$2/(42*1000) -> 7.3839537 | AP7: =$E7*AH$2/1000 -> 1.1739543 | AQ7: =$E7*AI$2/1000000 -> 4.9165566 | AS7: oil mass
A8: ='Texas pop'!A104 -> 2020 | B8: ='Texas pop'!B104 -> 29232474 | C8: ='Texas pop'!C104 -> 52200 | D8: ='Texas pop'!D104 -> 52200 | E8: ='Texas pop'!E104 -> 28700 | F8: =E8*$C$46*$D$45/1000000000 -> 0.39880684 | G8: =E8/1000*$D$41/0.9/1000 -> 16.542666 | H8: 0 | I8: =H8/$D$42*$D$43 -> 0 | J8: =$D$45*E8/1000 -> 5525.611 | K8: =J8-I7 -> 5525.611 | L8: =Q8 -> 429.62963 | M8: ='Plastics CCUS_RMTO'!M8 -> 429.62963 | N8: ='Plastics CCUS_RMTP'!M8 -> 429.62963 | O8: ='Plastics CCUS_ROCM'!M8 -> 429.62963 | P8: 2.32 | Q8: =$H$50/2.7*P8 -> 429.62963 | R8: =R7*(1-0.01) -> 1802.2128 | S8: ='Plastics CCUS_RMTO'!Q8 -> 1 | T8: ='Plastics CCUS_RMTP'!Q8 -> 1 | U8: ='Plastics CCUS_ROCM'!Q8 -> 1 | V8: =$E8*I$2/1000000 -> 0.40663341 | W8: =$E8*J$2/1000000 -> 0.37988121 | X8: =$E8*K$2/1000000 -> 0.57249703 | Y8: =$E8*L$2/1000000 -> 0.037453077 | Z8: =$E8*M$2/1000000 -> 0.037453077 | AA8: =$E8*P$2/1000000 -> 0.074906154 | AB8: =$E8*R$2/1000000 -> 0.074906154 | AC8: =$E8*S$2/1000000 -> 0.074906154 | AD8: =$E8*V$2/1000000 -> 0.058854835 | AE8: =$E8*W$2/1000000 -> 0.37453077 | AF8: =$E8*X$2/1000000 -> 0.18726538 | AG8: =$E8*Y$2/1000000 -> 0.090957472 | AH8: =$E8*Z$2/1000000 -> 0.96842956 | AI8: =$E8*AA$2/1000000 -> 0.65275362 | AJ8: =$E8*AB$2/1000000 -> 0.62065099 | AK8: =$E8*AC$2/1000000 -> 0.73836066 | AL8: =SUM(V8:AK8) -> 5.3504395 | AM8: =$E8*AE$2 -> 214170.66 | AN8: =$E8*AF$2/1000000 -> 6.0653131 | AO8: =$E8*AG$2/(42*1000) -> 15.356483 | AP8: =$E8*AH$2/1000 -> 2.4414846 | AQ8: =$E8*AI$2/1000000 -> 10.225013 | AS8: 7.2 | AT8: =AS8*AG2 -> 161.8049
A9: ='Texas pop'!A105 -> 2021 | B9: ='Texas pop'!B105 -> 29558864 | C9: ='Texas pop'!C105 -> 80900 | D9: ='Texas pop'!D105 -> 80900 | E9: ='Texas pop'!E105 -> 68100 | F9: =E9*$C$46*$D$45/1000000000 -> 0.94629776 | G9: =E9/1000*$D$41/0.9/1000 -> 39.252806 | H9: 0 | I9: =H9/$D$42*$D$43 -> 0 | J9: =$D$45*E9/1000 -> 13111.293 | K9: =J9-I8 -> 13111.293 | L9: =Q9 -> 511.11111 | M9: ='Plastics CCUS_RMTO'!M9 -> 511.11111 | N9: ='Plastics CCUS_RMTP'!M9 -> 511.11111 | O9: ='Plastics CCUS_ROCM'!M9 -> 511.11111 | P9: 2.76 | Q9: =$H$50/2.7*P9 -> 511.11111 | R9: =R8*(1-0.01) -> 1784.1907 | S9: ='Plastics CCUS_RMTO'!Q9 -> 1 | T9: ='Plastics CCUS_RMTP'!Q9 -> 1 | U9: ='Plastics CCUS_ROCM'!Q9 -> 1 | V9: =$E9*I$2/1000000 -> 0.96486881 | W9: =$E9*J$2/1000000 -> 0.9013906 | X9: =$E9*K$2/1000000 -> 1.3584337 | Y9: =$E9*L$2/1000000 -> 0.088869496 | Z9: =$E9*M$2/1000000 -> 0.088869496 | AA9: =$E9*P$2/1000000 -> 0.17773899 | AB9: =$E9*R$2/1000000 -> 0.17773899 | AC9: =$E9*S$2/1000000 -> 0.17773899 | AD9: =$E9*V$2/1000000 -> 0.13965206 | AE9: =$E9*W$2/1000000 -> 0.88869496 | AF9: =$E9*X$2/1000000 -> 0.44434748 | AG9: =$E9*Y$2/1000000 -> 0.21582592 | AH9: =$E9*Z$2/1000000 -> 2.2979113 | AI9: =$E9*AA$2/1000000 -> 1.5488684 | AJ9: =$E9*AB$2/1000000 -> 1.4726945 | AK9: =$E9*AC$2/1000000 -> 1.7519986 | AL9: =SUM(V9:AK9) -> 12.695642 | AM9: =$E9*AE$2 -> 508188.92 | AN9: =$E9*AF$2/1000000 -> 14.39191 | AO9: =$E9*AG$2/(42*1000) -> 36.438206 | AP9: =$E9*AH$2/1000 -> 5.7932091 | AQ9: =$E9*AI$2/1000000 -> 24.262138 | AS9: kgs | AT9: =AT5*AT8 -> 73.393408
A10: ='Texas pop'!A106 -> 2022 | B10: ='Texas pop'!B106 -> 30029572 | C10: ='Texas pop'!C106 -> 149000 | D10: ='Texas pop'!D106 -> 149000 | E10: ='Texas pop'!E106 -> 78996 | F10: =E10*$C$46*$D$45/1000000000 -> 1.0977054 | G10: =E10/1000*$D$41/0.9/1000 -> 45.533255 | H10: 0 | I10: =H10/$D$42*$D$43 -> 0 | J10: =$D$45*E10/1000 -> 15209.1 | K10: =J10-I9 -> 15209.1 | L10: =Q10 -> 901.85185 | M10: ='Plastics CCUS_RMTO'!M10 -> 901.85185 | N10: ='Plastics CCUS_RMTP'!M10 -> 901.85185 | O10: ='Plastics CCUS_ROCM'!M10 -> 901.85185 | P10: 4.87 | Q10: =$H$50/2.7*P10 -> 901.85185 | R10: =R9*(1-0.01) -> 1766.3488 | S10: ='Plastics CCUS_RMTO'!Q10 -> 1 | T10: ='Plastics CCUS_RMTP'!Q10 -> 1 | U10: ='Plastics CCUS_ROCM'!Q10 -> 1 | V10: =$E10*I$2/1000000 -> 1.1192478 | W10: =$E10*J$2/1000000 -> 1.0456131 | X10: =$E10*K$2/1000000 -> 1.5757831 | Y10: =$E10*L$2/1000000 -> 0.10308862 | Z10: =$E10*M$2/1000000 -> 0.10308862 | AA10: =$E10*P$2/1000000 -> 0.20617723 | AB10: =$E10*R$2/1000000 -> 0.20617723 | AC10: =$E10*S$2/1000000 -> 0.20617723 | AD10: =$E10*V$2/1000000 -> 0.1619964 | AE10: =$E10*W$2/1000000 -> 1.0308862 | AF10: =$E10*X$2/1000000 -> 0.51544308 | AG10: =$E10*Y$2/1000000 -> 0.25035807 | AH10: =$E10*Z$2/1000000 -> 2.6655771 | AI10: =$E10*AA$2/1000000 -> 1.7966873 | AJ10: =$E10*AB$2/1000000 -> 1.7083256 | AK10: =$E10*AC$2/1000000 -> 2.0323184 | AL10: =SUM(V10:AK10) -> 14.726945 | AM10: =$E10*AE$2 -> 589499.15 | AN10: =$E10*AF$2/1000000 -> 16.694616 | AO10: =$E10*AG$2/(42*1000) -> 42.268319 | AP10: =$E10*AH$2/1000 -> 6.7201226 | AQ10: =$E10*AI$2/1000000 -> 28.14408 | AS10: kgs | AT10: =AS4+AT9 -> 251.87144
A11: ='Texas pop'!A107 -> 2023 | B11: ='Texas pop'!B107 -> 30303924 | C11: ='Texas pop'!C107 -> 227996 | D11: ='Texas pop'!D107 -> 227996 | E11: ='Texas pop'!E107 -> 91635.36 | F11: =E11*$C$46*$D$45/1000000000 -> 1.2733383 | G11: =E11/1000*$D$41/0.9/1000 -> 52.818576 | H11: 0 | I11: =H11/$D$42*$D$43 -> 0 | J11: =$D$45*E11/1000 -> 17642.556 | K11: =J11-I10 -> 17642.556 | L11: =Q11 -> 831.48148 | M11: ='Plastics CCUS_RMTO'!M11 -> 831.48148 | N11: ='Plastics CCUS_RMTP'!M11 -> 831.48148 | O11: ='Plastics CCUS_ROCM'!M11 -> 831.48148 | P11: 4.49 | Q11: =$H$50/2.7*P11 -> 831.48148 | R11: =R10*(1-0.01) -> 1748.6853 | S11: ='Plastics CCUS_RMTO'!Q11 -> 1 | T11: ='Plastics CCUS_RMTP'!Q11 -> 1 | U11: ='Plastics CCUS_ROCM'!Q11 -> 1 | V11: =$E11*I$2/1000000 -> 1.2983275 | W11: =$E11*J$2/1000000 -> 1.2129112 | X11: =$E11*K$2/1000000 -> 1.8279084 | Y11: =$E11*L$2/1000000 -> 0.11958279 | Z11: =$E11*M$2/1000000 -> 0.11958279 | AA11: =$E11*P$2/1000000 -> 0.23916559 | AB11: =$E11*R$2/1000000 -> 0.23916559 | AC11: =$E11*S$2/1000000 -> 0.23916559 | AD11: =$E11*V$2/1000000 -> 0.18791582 | AE11: =$E11*W$2/1000000 -> 1.1958279 | AF11: =$E11*X$2/1000000 -> 0.59791397 | AG11: =$E11*Y$2/1000000 -> 0.29041536 | AH11: =$E11*Z$2/1000000 -> 3.0920694 | AI11: =$E11*AA$2/1000000 -> 2.0841573 | AJ11: =$E11*AB$2/1000000 -> 1.9816577 | AK11: =$E11*AC$2/1000000 -> 2.3574894 | AL11: =SUM(V11:AK11) -> 17.083256 | AM11: =$E11*AE$2 -> 683819.01 | AN11: =$E11*AF$2/1000000 -> 19.365754 | AO11: =$E11*AG$2/(42*1000) -> 49.03125 | AP11: =$E11*AH$2/1000 -> 7.7953422 | AQ11: =$E11*AI$2/1000000 -> 32.647133 | AS11: final | AT11: 186.43
A12: ='Texas pop'!A108 -> 2024 | B12: ='Texas pop'!B108 -> 30642857 | C12: ='Texas pop'!C108 -> 319631.36 | D12: ='Texas pop'!D108 -> 319631.36 | E12: ='Texas pop'!E108 -> 106297.02 | F12: =E12*$C$46*$D$45/1000000000 -> 1.4770724 | G12: =E12/1000*$D$41/0.9/1000 -> 61.269548 | H12: =E12*$D$41/1000 -> 55142.593 | I12: =H12/$D$42*$D$43 -> 12182.666 | J12: =$D$45*E12/1000 -> 20465.365 | K12: =J12-I11 -> 20465.365 | L12: =Q12 -> 833.33333 | M12: ='Plastics CCUS_RMTO'!M12 -> 833.33333 | N12: ='Plastics CCUS_RMTP'!M12 -> 833.33333 | O12: ='Plastics CCUS_ROCM'!M12 -> 833.33333 | P12: 4.5 | Q12: =$H$50/2.7*P12 -> 833.33333 | R12: =R11*(1-0.01) -> 1731.1984 | S12: ='Plastics CCUS_RMTO'!Q12 -> 1 | T12: ='Plastics CCUS_RMTP'!Q12 -> 1 | U12: ='Plastics CCUS_ROCM'!Q12 -> 1 | V12: =$E12*I$2/1000000 -> 1.5060599 | W12: =$E12*J$2/1000000 -> 1.406977 | X12: =$E12*K$2/1000000 -> 2.1203738 | Y12: =$E12*L$2/1000000 -> 0.13871604 | Z12: =$E12*M$2/1000000 -> 0.13871604 | AA12: =$E12*P$2/1000000 -> 0.27743208 | AB12: =$E12*R$2/1000000 -> 0.27743208 | AC12: =$E12*S$2/1000000 -> 0.27743208 | AD12: =$E12*V$2/1000000 -> 0.21798235 | AE12: =$E12*W$2/1000000 -> 1.3871604 | AF12: =$E12*X$2/1000000 -> 0.6935802 | AG12: =$E12*Y$2/1000000 -> 0.33688181 | AH12: =$E12*Z$2/1000000 -> 3.5868005 | AI12: =$E12*AA$2/1000000 -> 2.4176224 | AJ12: =$E12*AB$2/1000000 -> 2.298723 | AK12: =$E12*AC$2/1000000 -> 2.7346877 | AL12: =SUM(V12:AK12) -> 19.816577 | AM12: =$E12*AE$2 -> 793230.05 | AN12: =$E12*AF$2/1000000 -> 22.464275 | AO12: =$E12*AG$2/(42*1000) -> 56.87625 | AP12: =$E12*AH$2/1000 -> 9.0425969 | AQ12: =$E12*AI$2/1000000 -> 37.870674 | AS12: Mass req/kg output | AT12: =AT10/AT11 -> 1.3510242
A13: ='Texas pop'!A109 -> 2025 | B13: ='Texas pop'!B109 -> 30981790 | C13: ='Texas pop'!C109 -> 425928.38 | D13: ='Texas pop'!D109 -> 425928.38 | E13: ='Texas pop'!E109 -> 123304.54 | F13: =E13*$C$46*$D$45/1000000000 -> 1.713404 | G13: =E13/1000*$D$41/0.9/1000 -> 71.072675 | H13: =E13*$D$41/1000 -> 63965.408 | I13: =H13/$D$42*$D$43 -> 14131.892 | J13: =$D$45*E13/1000 -> 23739.823 | K13: =J13-I12 -> 11557.157 | L13: =Q13 -> 840.74074 | M13: ='Plastics CCUS_RMTO'!M13 -> 1288.8166 | N13: ='Plastics CCUS_RMTP'!M13 -> 1330.9965 | O13: ='Plastics CCUS_ROCM'!M13 -> 1248.9627 | P13: 4.54 | Q13: =$H$50/2.7*P13 -> 840.74074 | R13: =R12*(1-0.01) -> 1713.8865 | S13: ='Plastics CCUS_RMTO'!Q13 -> 1.5329537 | T13: ='Plastics CCUS_RMTP'!Q13 -> 1.5831236 | U13: ='Plastics CCUS_ROCM'!Q13 -> 1.4855503 | V13: =$E13*I$2/1000000 -> 1.7470294 | W13: =$E13*J$2/1000000 -> 1.6320933 | X13: =$E13*K$2/1000000 -> 2.4596336 | Y13: =$E13*L$2/1000000 -> 0.16091061 | Z13: =$E13*M$2/1000000 -> 0.16091061 | AA13: =$E13*P$2/1000000 -> 0.32182121 | AB13: =$E13*R$2/1000000 -> 0.32182121 | AC13: =$E13*S$2/1000000 -> 0.32182121 | AD13: =$E13*V$2/1000000 -> 0.25285953 | AE13: =$E13*W$2/1000000 -> 1.6091061 | AF13: =$E13*X$2/1000000 -> 0.80455304 | AG13: =$E13*Y$2/1000000 -> 0.3907829 | AH13: =$E13*Z$2/1000000 -> 4.1606886 | AI13: =$E13*AA$2/1000000 -> 2.804442 | AJ13: =$E13*AB$2/1000000 -> 2.6665186 | AK13: =$E13*AC$2/1000000 -> 3.1722377 | AL13: =SUM(V13:AK13) -> 22.98723 | AM13: =$E13*AE$2 -> 920146.86 | AN13: =$E13*AF$2/1000000 -> 26.058559 | AO13: =$E13*AG$2/(42*1000) -> 65.976451 | AP13: =$E13*AH$2/1000 -> 10.489412 | AQ13: =$E13*AI$2/1000000 -> 43.929982
A14: ='Texas pop'!A110 -> 2026 | B14: ='Texas pop'!B110 -> 31320722 | C14: ='Texas pop'!C110 -> 549232.92 | D14: ='Texas pop'!D110 -> 549232.92 | E14: ='Texas pop'!E110 -> 143033.27 | F14: =E14*$C$46*$D$45/1000000000 -> 1.9875486 | G14: =E14/1000*$D$41/0.9/1000 -> 82.444304 | H14: =E14*$D$41/1000 -> 74199.873 | I14: =H14/$D$42*$D$43 -> 16392.995 | J14: =$D$45*E14/1000 -> 27538.195 | K14: =J14-I13 -> 13406.302 | L14: =Q14 -> 848.14815 | M14: ='Plastics CCUS_RMTO'!M14 -> 1283.6275 | N14: ='Plastics CCUS_RMTP'!M14 -> 1326.231 | O14: ='Plastics CCUS_ROCM'!M14 -> 1247.441 | P14: 4.58 | Q14: =$H$50/2.7*P14 -> 848.14815 | R14: =R13*(1-0.01) -> 1696.7476 | S14: ='Plastics CCUS_RMTO'!Q14 -> 1.5134473 | T14: ='Plastics CCUS_RMTP'!Q14 -> 1.5636785 | U14: ='Plastics CCUS_ROCM'!Q14 -> 1.4707819 | V14: =$E14*I$2/1000000 -> 2.0265542 | W14: =$E14*J$2/1000000 -> 1.8932282 | X14: =$E14*K$2/1000000 -> 2.8531749 | Y14: =$E14*L$2/1000000 -> 0.1866563 | Z14: =$E14*M$2/1000000 -> 0.1866563 | AA14: =$E14*P$2/1000000 -> 0.37331261 | AB14: =$E14*R$2/1000000 -> 0.37331261 | AC14: =$E14*S$2/1000000 -> 0.37331261 | AD14: =$E14*V$2/1000000 -> 0.29331705 | AE14: =$E14*W$2/1000000 -> 1.866563 | AF14: =$E14*X$2/1000000 -> 0.93328152 | AG14: =$E14*Y$2/1000000 -> 0.45330817 | AH14: =$E14*Z$2/1000000 -> 4.8263987 | AI14: =$E14*AA$2/1000000 -> 3.2531527 | AJ14: =$E14*AB$2/1000000 -> 3.0931616 | AK14: =$E14*AC$2/1000000 -> 3.6797957 | AL14: =SUM(V14:AK14) -> 26.665186 | AM14: =$E14*AE$2 -> 1067370.4 | AN14: =$E14*AF$2/1000000 -> 30.227929 | AO14: =$E14*AG$2/(42*1000) -> 76.532683 | AP14: =$E14*AH$2/1000 -> 12.167718 | AQ14: =$E14*AI$2/1000000 -> 50.958779
A15: ='Texas pop'!A111 -> 2027 | B15: ='Texas pop'!B111 -> 31659655 | C15: ='Texas pop'!C111 -> 692266.18 | D15: ='Texas pop'!D111 -> 692266.18 | E15: ='Texas pop'!E111 -> 165918.59 | F15: =E15*$C$46*$D$45/1000000000 -> 2.3055564 | G15: =E15/1000*$D$41/0.9/1000 -> 95.635392 | H15: =E15*$D$41/1000 -> 86071.853 | I15: =H15/$D$42*$D$43 -> 19015.874 | J15: =$D$45*E15/1000 -> 31944.306 | K15: =J15-I14 -> 15551.311 | L15: =Q15 -> 888.88889 | M15: ='Plastics CCUS_RMTO'!M15 -> 1294.7539 | N15: ='Plastics CCUS_RMTP'!M15 -> 1339.5626 | O15: ='Plastics CCUS_ROCM'!M15 -> 1269.1032 | P15: 4.8 | Q15: =$H$50/2.7*P15 -> 888.88889 | R15: =R14*(1-0.01) -> 1679.7801 | S15: ='Plastics CCUS_RMTO'!Q15 -> 1.4565981 | T15: ='Plastics CCUS_RMTP'!Q15 -> 1.5070079 | U15: ='Plastics CCUS_ROCM'!Q15 -> 1.4277411 | V15: =$E15*I$2/1000000 -> 2.3508028 | W15: =$E15*J$2/1000000 -> 2.1961447 | X15: =$E15*K$2/1000000 -> 3.3096829 | Y15: =$E15*L$2/1000000 -> 0.21652131 | Z15: =$E15*M$2/1000000 -> 0.21652131 | AA15: =$E15*P$2/1000000 -> 0.43304263 | AB15: =$E15*R$2/1000000 -> 0.43304263 | AC15: =$E15*S$2/1000000 -> 0.43304263 | AD15: =$E15*V$2/1000000 -> 0.34024778 | AE15: =$E15*W$2/1000000 -> 2.1652131 | AF15: =$E15*X$2/1000000 -> 1.0826066 | AG15: =$E15*Y$2/1000000 -> 0.52583747 | AH15: =$E15*Z$2/1000000 -> 5.5986225 | AI15: =$E15*AA$2/1000000 -> 3.7736572 | AJ15: =$E15*AB$2/1000000 -> 3.5880675 | AK15: =$E15*AC$2/1000000 -> 4.268563 | AL15: =SUM(V15:AK15) -> 30.931616 | AM15: =$E15*AE$2 -> 1238149.6 | AN15: =$E15*AF$2/1000000 -> 35.064397 | AO15: =$E15*AG$2/(42*1000) -> 88.777912 | AP15: =$E15*AH$2/1000 -> 14.114553 | AQ15: =$E15*AI$2/1000000 -> 59.112183
A16: ='Texas pop'!A112 -> 2028 | B16: ='Texas pop'!B112 -> 31998588 | C16: ='Texas pop'!C112 -> 858184.77 | D16: ='Texas pop'!D112 -> 858184.77 | E16: ='Texas pop'!E112 -> 192465.56 | F16: =E16*$C$46*$D$45/1000000000 -> 2.6744454 | G16: =E16/1000*$D$41/0.9/1000 -> 110.93705 | H16: =E16*$D$41/1000 -> 99843.349 | I16: =H16/$D$42*$D$43 -> 22058.414 | J16: =$D$45*E16/1000 -> 37055.395 | K16: =J16-I15 -> 18039.521 | L16: =Q16 -> 907.40741 | M16: ='Plastics CCUS_RMTO'!M16 -> 1295.149 | N16: ='Plastics CCUS_RMTP'!M16 -> 1340.9747 | O16: ='Plastics CCUS_ROCM'!M16 -> 1275.4198 | P16: 4.9 | Q16: =$H$50/2.7*P16 -> 907.40741 | R16: =R15*(1-0.01) -> 1662.9823 | S16: ='Plastics CCUS_RMTO'!Q16 -> 1.4273071 | T16: ='Plastics CCUS_RMTP'!Q16 -> 1.4778088 | U16: ='Plastics CCUS_ROCM'!Q16 -> 1.4055646 | V16: =$E16*I$2/1000000 -> 2.7269313 | W16: =$E16*J$2/1000000 -> 2.5475279 | X16: =$E16*K$2/1000000 -> 3.8392322 | Y16: =$E16*L$2/1000000 -> 0.25116472 | Z16: =$E16*M$2/1000000 -> 0.25116472 | AA16: =$E16*P$2/1000000 -> 0.50232945 | AB16: =$E16*R$2/1000000 -> 0.50232945 | AC16: =$E16*S$2/1000000 -> 0.50232945 | AD16: =$E16*V$2/1000000 -> 0.39468742 | AE16: =$E16*W$2/1000000 -> 2.5116472 | AF16: =$E16*X$2/1000000 -> 1.2558236 | AG16: =$E16*Y$2/1000000 -> 0.60997147 | AH16: =$E16*Z$2/1000000 -> 6.4944021 | AI16: =$E16*AA$2/1000000 -> 4.3774423 | AJ16: =$E16*AB$2/1000000 -> 4.1621583 | AK16: =$E16*AC$2/1000000 -> 4.9515331 | AL16: =SUM(V16:AK16) -> 35.880675 | AM16: =$E16*AE$2 -> 1436253.6 | AN16: =$E16*AF$2/1000000 -> 40.674701 | AO16: =$E16*AG$2/(42*1000) -> 102.98238 | AP16: =$E16*AH$2/1000 -> 16.372882 | AQ16: =$E16*AI$2/1000000 -> 68.570133
A17: ='Texas pop'!A113 -> 2029 | B17: ='Texas pop'!B113 -> 32337520 | C17: ='Texas pop'!C113 -> 1050650.3 | D17: ='Texas pop'!D113 -> 1050650.3 | E17: ='Texas pop'!E113 -> 223260.05 | F17: =E17*$C$46*$D$45/1000000000 -> 3.1023567 | G17: =E17/1000*$D$41/0.9/1000 -> 128.68698 | H17: =E17*$D$41/1000 -> 115818.29 | I17: =H17/$D$42*$D$43 -> 25587.761 | J17: =$D$45*E17/1000 -> 42984.258 | K17: =J17-I16 -> 20925.844 | L17: =Q17 -> 944.44444 | M17: ='Plastics CCUS_RMTO'!M17 -> 1304.6456 | N17: ='Plastics CCUS_RMTP'!M17 -> 1352.4779 | O17: ='Plastics CCUS_ROCM'!M17 -> 1294.6446 | P17: 5.1 | Q17: =$H$50/2.7*P17 -> 944.44444 | R17: =R16*(1-0.01) -> 1646.3525 | S17: ='Plastics CCUS_RMTO'!Q17 -> 1.3813894 | T17: ='Plastics CCUS_RMTP'!Q17 -> 1.4320354 | U17: ='Plastics CCUS_ROCM'!Q17 -> 1.3708002 | V17: =$E17*I$2/1000000 -> 3.1632403 | W17: =$E17*J$2/1000000 -> 2.9551324 | X17: =$E17*K$2/1000000 -> 4.4535093 | Y17: =$E17*L$2/1000000 -> 0.29135108 | Z17: =$E17*M$2/1000000 -> 0.29135108 | AA17: =$E17*P$2/1000000 -> 0.58270216 | AB17: =$E17*R$2/1000000 -> 0.58270216 | AC17: =$E17*S$2/1000000 -> 0.58270216 | AD17: =$E17*V$2/1000000 -> 0.45783741 | AE17: =$E17*W$2/1000000 -> 2.9135108 | AF17: =$E17*X$2/1000000 -> 1.4567554 | AG17: =$E17*Y$2/1000000 -> 0.70756691 | AH17: =$E17*Z$2/1000000 -> 7.5335065 | AI17: =$E17*AA$2/1000000 -> 5.0778331 | AJ17: =$E17*AB$2/1000000 -> 4.8281036 | AK17: =$E17*AC$2/1000000 -> 5.7437784 | AL17: =SUM(V17:AK17) -> 41.621583 | AM17: =$E17*AE$2 -> 1666054.1 | AN17: =$E17*AF$2/1000000 -> 47.182653 | AO17: =$E17*AG$2/(42*1000) -> 119.45956 | AP17: =$E17*AH$2/1000 -> 18.992543 | AQ17: =$E17*AI$2/1000000 -> 79.541354
A18: ='Texas pop'!A114 -> 2030 | B18: ='Texas pop'!B114 -> 32676453 | C18: ='Texas pop'!C114 -> 1273910.4 | D18: ='Texas pop'!D114 -> 1273910.4 | E18: ='Texas pop'!E114 -> 258981.66 | F18: =E18*$C$46*$D$45/1000000000 -> 3.5987337 | G18: =E18/1000*$D$41/0.9/1000 -> 149.2769 | H18: =E18*$D$41/1000 -> 134349.21 | I18: =H18/$D$42*$D$43 -> 29681.802 | J18: =$D$45*E18/1000 -> 49861.74 | K18: =J18-I17 -> 24273.979 | L18: =Q18 -> 962.96296 | M18: ='Plastics CCUS_RMTO'!M18 -> 1305.2122 | N18: ='Plastics CCUS_RMTP'!M18 -> 1354.061 | O18: ='Plastics CCUS_ROCM'!M18 -> 1301.0911 | P18: 5.2 | Q18: =$H$50/2.7*P18 -> 962.96296 | R18: =R17*(1-0.01) -> 1629.889 | S18: ='Plastics CCUS_RMTO'!Q18 -> 1.3554127 | T18: ='Plastics CCUS_RMTP'!Q18 -> 1.4061402 | U18: ='Plastics CCUS_ROCM'!Q18 -> 1.351133 | V18: =$E18*I$2/1000000 -> 3.6693587 | W18: =$E18*J$2/1000000 -> 3.4279535 | X18: =$E18*K$2/1000000 -> 5.1660708 | Y18: =$E18*L$2/1000000 -> 0.33796725 | Z18: =$E18*M$2/1000000 -> 0.33796725 | AA18: =$E18*P$2/1000000 -> 0.6759345 | AB18: =$E18*R$2/1000000 -> 0.6759345 | AC18: =$E18*S$2/1000000 -> 0.6759345 | AD18: =$E18*V$2/1000000 -> 0.53109139 | AE18: =$E18*W$2/1000000 -> 3.3796725 | AF18: =$E18*X$2/1000000 -> 1.6898363 | AG18: =$E18*Y$2/1000000 -> 0.82077761 | AH18: =$E18*Z$2/1000000 -> 8.7388675 | AI18: =$E18*AA$2/1000000 -> 5.8902864 | AJ18: =$E18*AB$2/1000000 -> 5.6006002 | AK18: =$E18*AC$2/1000000 -> 6.662783 | AL18: =SUM(V18:AK18) -> 48.281036 | AM18: =$E18*AE$2 -> 1932622.8 | AN18: =$E18*AF$2/1000000 -> 54.731877 | AO18: =$E18*AG$2/(42*1000) -> 138.57309 | AP18: =$E18*AH$2/1000 -> 22.03135 | AQ18: =$E18*AI$2/1000000 -> 92.267971
A19: ='Texas pop'!A115 -> 2031 | B19: ='Texas pop'!B115 -> 33015385 | C19: ='Texas pop'!C115 -> 1532892.1 | D19: ='Texas pop'!D115 -> 1532892.1 | E19: ='Texas pop'!E115 -> 282290.01 | F19: =E19*$C$46*$D$45/1000000000 -> 3.9226198 | G19: =E19/1000*$D$41/0.9/1000 -> 162.71182 | H19: =E19*$D$41/1000 -> 146440.64 | I19: =H19/$D$42*$D$43 -> 32353.165 | J19: =$D$45*E19/1000 -> 54349.296 | K19: =J19-I18 -> 24667.494 | L19: =Q19 -> 981.48148 | M19: ='Plastics CCUS_RMTO'!M19 -> 1326.6952 | N19: ='Plastics CCUS_RMTP'!M19 -> 1379.7625 | O19: ='Plastics CCUS_ROCM'!M19 -> 1328.545 | P19: 5.3 | Q19: =$H$50/2.7*P19 -> 981.48148 | R19: =R18*(1-0.01) -> 1613.5901 | S19: ='Plastics CCUS_RMTO'!Q19 -> 1.3517272 | T19: ='Plastics CCUS_RMTP'!Q19 -> 1.4057957 | U19: ='Plastics CCUS_ROCM'!Q19 -> 1.3536118 | V19: =$E19*I$2/1000000 -> 3.999601 | W19: =$E19*J$2/1000000 -> 3.7364694 | X19: =$E19*K$2/1000000 -> 5.6310172 | Y19: =$E19*L$2/1000000 -> 0.3683843 | Z19: =$E19*M$2/1000000 -> 0.3683843 | AA19: =$E19*P$2/1000000 -> 0.73676861 | AB19: =$E19*R$2/1000000 -> 0.73676861 | AC19: =$E19*S$2/1000000 -> 0.73676861 | AD19: =$E19*V$2/1000000 -> 0.57888962 | AE19: =$E19*W$2/1000000 -> 3.683843 | AF19: =$E19*X$2/1000000 -> 1.8419215 | AG19: =$E19*Y$2/1000000 -> 0.8946476 | AH19: =$E19*Z$2/1000000 -> 9.5253656 | AI19: =$E19*AA$2/1000000 -> 6.4204122 | AJ19: =$E19*AB$2/1000000 -> 6.1046542 | AK19: =$E19*AC$2/1000000 -> 7.2624334 | AL19: =SUM(V19:AK19) -> 52.626329 | AM19: =$E19*AE$2 -> 2106558.8 | AN19: =$E19*AF$2/1000000 -> 59.657746 | AO19: =$E19*AG$2/(42*1000) -> 151.04467 | AP19: =$E19*AH$2/1000 -> 24.014171 | AQ19: =$E19*AI$2/1000000 -> 100.57209
A20: ='Texas pop'!A116 -> 2032 | B20: ='Texas pop'!B116 -> 33354318 | C20: ='Texas pop'!C116 -> 1815182.1 | D20: ='Texas pop'!D116 -> 1815182.1 | E20: ='Texas pop'!E116 -> 307696.11 | F20: =E20*$C$46*$D$45/1000000000 -> 4.2756556 | G20: =E20/1000*$D$41/0.9/1000 -> 177.35589 | H20: =E20*$D$41/1000 -> 159620.3 | I20: =H20/$D$42*$D$43 -> 35264.949 | J20: =$D$45*E20/1000 -> 59240.733 | K20: =J20-I19 -> 26887.568 | L20: =Q20 -> 1000 | M20: ='Plastics CCUS_RMTO'!M20 -> 1326.2879 | N20: ='Plastics CCUS_RMTP'!M20 -> 1380.4363 | O20: ='Plastics CCUS_ROCM'!M20 -> 1334.3516 | P20: 5.4 | Q20: =$H$50/2.7*P20 -> 1000 | R20: =R19*(1-0.01) -> 1597.4542 | S20: ='Plastics CCUS_RMTO'!Q20 -> 1.3262879 | T20: ='Plastics CCUS_RMTP'!Q20 -> 1.3804363 | U20: ='Plastics CCUS_ROCM'!Q20 -> 1.3343516 | V20: =$E20*I$2/1000000 -> 4.3595651 | W20: =$E20*J$2/1000000 -> 4.0727516 | X20: =$E20*K$2/1000000 -> 6.1378088 | Y20: =$E20*L$2/1000000 -> 0.40153889 | Z20: =$E20*M$2/1000000 -> 0.40153889 | AA20: =$E20*P$2/1000000 -> 0.80307778 | AB20: =$E20*R$2/1000000 -> 0.80307778 | AC20: =$E20*S$2/1000000 -> 0.80307778 | AD20: =$E20*V$2/1000000 -> 0.63098969 | AE20: =$E20*W$2/1000000 -> 4.0153889 | AF20: =$E20*X$2/1000000 -> 2.0076945 | AG20: =$E20*Y$2/1000000 -> 0.97516588 | AH20: =$E20*Z$2/1000000 -> 10.382648 | AI20: =$E20*AA$2/1000000 -> 6.9982492 | AJ20: =$E20*AB$2/1000000 -> 6.6540731 | AK20: =$E20*AC$2/1000000 -> 7.9160524 | AL20: =SUM(V20:AK20) -> 57.362699 | AM20: =$E20*AE$2 -> 2296149.1 | AN20: =$E20*AF$2/1000000 -> 65.026943 | AO20: =$E20*AG$2/(42*1000) -> 164.63869 | AP20: =$E20*AH$2/1000 -> 26.175447 | AQ20: =$E20*AI$2/1000000 -> 109.62358
A21: ='Texas pop'!A117 -> 2033 | B21: ='Texas pop'!B117 -> 33693251 | C21: ='Texas pop'!C117 -> 2122878.2 | D21: ='Texas pop'!D117 -> 2122878.2 | E21: ='Texas pop'!E117 -> 335388.76 | F21: =E21*$C$46*$D$45/1000000000 -> 4.6604646 | G21: =E21/1000*$D$41/0.9/1000 -> 193.31792 | H21: =E21*$D$41/1000 -> 173986.12 | I21: =H21/$D$42*$D$43 -> 38438.795 | J21: =$D$45*E21/1000 -> 64572.399 | K21: =J21-I20 -> 29307.449 | L21: =Q21 -> 996.2963 | M21: ='Plastics CCUS_RMTO'!M21 -> 1315.8827 | N21: ='Plastics CCUS_RMTP'!M21 -> 1369.8479 | O21: ='Plastics CCUS_ROCM'!M21 -> 1325.2508 | P21: 5.38 | Q21: =$H$50/2.7*P21 -> 996.2963 | R21: =R20*(1-0.01) -> 1581.4796 | S21: ='Plastics CCUS_RMTO'!Q21 -> 1.3207745 | T21: ='Plastics CCUS_RMTP'!Q21 -> 1.3749402 | U21: ='Plastics CCUS_ROCM'!Q21 -> 1.3301774 | V21: =$E21*I$2/1000000 -> 4.751926 | W21: =$E21*J$2/1000000 -> 4.4392993 | X21: =$E21*K$2/1000000 -> 6.6902116 | Y21: =$E21*L$2/1000000 -> 0.43767739 | Z21: =$E21*M$2/1000000 -> 0.43767739 | AA21: =$E21*P$2/1000000 -> 0.87535478 | AB21: =$E21*R$2/1000000 -> 0.87535478 | AC21: =$E21*S$2/1000000 -> 0.87535478 | AD21: =$E21*V$2/1000000 -> 0.68777876 | AE21: =$E21*W$2/1000000 -> 4.3767739 | AF21: =$E21*X$2/1000000 -> 2.188387 | AG21: =$E21*Y$2/1000000 -> 1.0629308 | AH21: =$E21*Z$2/1000000 -> 11.317087 | AI21: =$E21*AA$2/1000000 -> 7.6280917 | AJ21: =$E21*AB$2/1000000 -> 7.2529396 | AK21: =$E21*AC$2/1000000 -> 8.6284971 | AL21: =SUM(V21:AK21) -> 62.525342 | AM21: =$E21*AE$2 -> 2502802.5 | AN21: =$E21*AF$2/1000000 -> 70.879368 | AO21: =$E21*AG$2/(42*1000) -> 179.45617 | AP21: =$E21*AH$2/1000 -> 28.531237 | AQ21: =$E21*AI$2/1000000 -> 119.4897
A22: ='Texas pop'!A118 -> 2034 | B22: ='Texas pop'!B118 -> 34032183 | C22: ='Texas pop'!C118 -> 2458266.9 | D22: ='Texas pop'!D118 -> 2458266.9 | E22: ='Texas pop'!E118 -> 365573.75 | F22: =E22*$C$46*$D$45/1000000000 -> 5.0799064 | G22: =E22/1000*$D$41/0.9/1000 -> 210.71653 | H22: =E22*$D$41/1000 -> 189644.88 | I22: =H22/$D$42*$D$43 -> 41898.286 | J22: =$D$45*E22/1000 -> 70383.915 | K22: =J22-I21 -> 31945.12 | L22: =Q22 -> 985.18519 | M22: ='Plastics CCUS_RMTO'!M22 -> 1302.2028 | N22: ='Plastics CCUS_RMTP'!M22 -> 1355.563 | O22: ='Plastics CCUS_ROCM'!M22 -> 1311.2246 | P22: 5.32 | Q22: =$H$50/2.7*P22 -> 985.18519 | R22: =R21*(1-0.01) -> 1565.6648 | S22: ='Plastics CCUS_RMTO'!Q22 -> 1.3217848 | T22: ='Plastics CCUS_RMTP'!Q22 -> 1.3759474 | U22: ='Plastics CCUS_ROCM'!Q22 -> 1.3309423 | V22: =$E22*I$2/1000000 -> 5.1795993 | W22: =$E22*J$2/1000000 -> 4.8388362 | X22: =$E22*K$2/1000000 -> 7.2923306 | Y22: =$E22*L$2/1000000 -> 0.47706836 | Z22: =$E22*M$2/1000000 -> 0.47706836 | AA22: =$E22*P$2/1000000 -> 0.95413671 | AB22: =$E22*R$2/1000000 -> 0.95413671 | AC22: =$E22*S$2/1000000 -> 0.95413671 | AD22: =$E22*V$2/1000000 -> 0.74967885 | AE22: =$E22*W$2/1000000 -> 4.7706836 | AF22: =$E22*X$2/1000000 -> 2.3853418 | AG22: =$E22*Y$2/1000000 -> 1.1585946 | AH22: =$E22*Z$2/1000000 -> 12.335625 | AI22: =$E22*AA$2/1000000 -> 8.3146199 | AJ22: =$E22*AB$2/1000000 -> 7.9057042 | AK22: =$E22*AC$2/1000000 -> 9.4050619 | AL22: =SUM(V22:AK22) -> 68.152622 | AM22: =$E22*AE$2 -> 2728054.8 | AN22: =$E22*AF$2/1000000 -> 77.258511 | AO22: =$E22*AG$2/(42*1000) -> 195.60722 | AP22: =$E22*AH$2/1000 -> 31.099048 | AQ22: =$E22*AI$2/1000000 -> 130.24377
A23: ='Texas pop'!A119 -> 2035 | B23: ='Texas pop'!B119 -> 34371116 | C23: ='Texas pop'!C119 -> 2823840.7 | D23: ='Texas pop'!D119 -> 2823840.7 | E23: ='Texas pop'!E119 -> 398475.39 | F23: =E23*$C$46*$D$45/1000000000 -> 5.537098 | G23: =E23/1000*$D$41/0.9/1000 -> 229.68102 | H23: =E23*$D$41/1000 -> 206712.91 | I23: =H23/$D$42*$D$43 -> 45669.132 | J23: =$D$45*E23/1000 -> 76718.467 | K23: =J23-I22 -> 34820.18 | L23: =Q23 -> 994.44444 | M23: ='Plastics CCUS_RMTO'!M23 -> 1297.8547 | N23: ='Plastics CCUS_RMTP'!M23 -> 1351.7685 | O23: ='Plastics CCUS_ROCM'!M23 -> 1310.9902 | P23: 5.37 | Q23: =$H$50/2.7*P23 -> 994.44444 | R23: =R22*(1-0.01) -> 1550.0082 | S23: ='Plastics CCUS_RMTO'!Q23 -> 1.3051053 | T23: ='Plastics CCUS_RMTP'!Q23 -> 1.3593203 | U23: ='Plastics CCUS_ROCM'!Q23 -> 1.3183141 | V23: =$E23*I$2/1000000 -> 5.6457632 | W23: =$E23*J$2/1000000 -> 5.2743314 | X23: =$E23*K$2/1000000 -> 7.9486403 | Y23: =$E23*L$2/1000000 -> 0.52000451 | Z23: =$E23*M$2/1000000 -> 0.52000451 | AA23: =$E23*P$2/1000000 -> 1.040009 | AB23: =$E23*R$2/1000000 -> 1.040009 | AC23: =$E23*S$2/1000000 -> 1.040009 | AD23: =$E23*V$2/1000000 -> 0.81714994 | AE23: =$E23*W$2/1000000 -> 5.2000451 | AF23: =$E23*X$2/1000000 -> 2.6000225 | AG23: =$E23*Y$2/1000000 -> 1.2628681 | AH23: =$E23*Z$2/1000000 -> 13.445831 | AI23: =$E23*AA$2/1000000 -> 9.0629357 | AJ23: =$E23*AB$2/1000000 -> 8.6172176 | AK23: =$E23*AC$2/1000000 -> 10.251517 | AL23: =SUM(V23:AK23) -> 74.286358 | AM23: =$E23*AE$2 -> 2973579.7 | AN23: =$E23*AF$2/1000000 -> 84.211777 | AO23: =$E23*AG$2/(42*1000) -> 213.21187 | AP23: =$E23*AH$2/1000 -> 33.897963 | AQ23: =$E23*AI$2/1000000 -> 141.96571
A24: ='Texas pop'!A120 -> 2036 | B24: ='Texas pop'!B120 -> 34710049 | C24: ='Texas pop'!C120 -> 3222316.1 | D24: ='Texas pop'!D120 -> 3210416.1 | E24: ='Texas pop'!E120 -> 434338.18 | F24: =E24*$C$46*$D$45/1000000000 -> 6.0354368 | G24: =E24/1000*$D$41/0.9/1000 -> 250.35231 | H24: =E24*$D$41/1000 -> 225317.08 | I24: =H24/$D$42*$D$43 -> 49779.354 | J24: =$D$45*E24/1000 -> 83623.129 | K24: =J24-I23 -> 37953.997 | L24: =Q24 -> 962.96296 | M24: ='Plastics CCUS_RMTO'!M24 -> 1275.1011 | N24: ='Plastics CCUS_RMTP'!M24 -> 1327.2506 | O24: ='Plastics CCUS_ROCM'!M24 -> 1283.3678 | P24: 5.2 | Q24: =$H$50/2.7*P24 -> 962.96296 | R24: =R23*(1-0.01) -> 1534.5081 | S24: ='Plastics CCUS_RMTO'!Q24 -> 1.3241435 | T24: ='Plastics CCUS_RMTP'!Q24 -> 1.3782987 | U24: ='Plastics CCUS_ROCM'!Q24 -> 1.3327281 | V24: =$E24*I$2/1000000 -> 6.1538819 | W24: =$E24*J$2/1000000 -> 5.7490213 | X24: =$E24*K$2/1000000 -> 8.664018 | Y24: =$E24*L$2/1000000 -> 0.56680491 | Z24: =$E24*M$2/1000000 -> 0.56680491 | AA24: =$E24*P$2/1000000 -> 1.1336098 | AB24: =$E24*R$2/1000000 -> 1.1336098 | AC24: =$E24*S$2/1000000 -> 1.1336098 | AD24: =$E24*V$2/1000000 -> 0.89069344 | AE24: =$E24*W$2/1000000 -> 5.6680491 | AF24: =$E24*X$2/1000000 -> 2.8340246 | AG24: =$E24*Y$2/1000000 -> 1.3765262 | AH24: =$E24*Z$2/1000000 -> 14.655956 | AI24: =$E24*AA$2/1000000 -> 9.8785999 | AJ24: =$E24*AB$2/1000000 -> 9.3927672 | AK24: =$E24*AC$2/1000000 -> 11.174154 | AL24: =SUM(V24:AK24) -> 80.972131 | AM24: =$E24*AE$2 -> 3241201.9 | AN24: =$E24*AF$2/1000000 -> 91.790837 | AO24: =$E24*AG$2/(42*1000) -> 232.40094 | AP24: =$E24*AH$2/1000 -> 36.948779 | AQ24: =$E24*AI$2/1000000 -> 154.74262
... A38: ='Texas pop'!A134 -> 2050 | B38: ='Texas pop'!B134 -> 39455106 | C38: ='Texas pop'!C134 -> 12569590 | D38: ='Texas pop'!D134 -> 11045098 | E38: ='Texas pop'!E134 -> 907543.37 | F38: =E38*$C$46*$D$45/1000000000 -> 12.610958 | G38: =E38/1000*$D$41/0.9/1000 -> 523.10754 | H38: =E38*$D$41/1000 -> 470796.79 | I38: =H38/$D$42*$D$43 -> 104013.24 | J38: =$D$45*E38/1000 -> 174729.32 | K38: =J38-I37 -> 74716.59 | L38: =Q38 -> 1000 | M38: ='Plastics CCUS_RMTO'!M38 -> 1190.6606 | N38: ='Plastics CCUS_RMTP'!M38 -> 1247.8876 | O38: ='Plastics CCUS_ROCM'!M38 -> 1235.8653 | P38: 5.4 | Q38: =$H$50/2.7*P38 -> 1000 | R38: =R37*(1-0.01) -> 1333.0975 | S38: ='Plastics CCUS_RMTO'!Q38 -> 1.1906606 | T38: ='Plastics CCUS_RMTP'!Q38 -> 1.2478876 | U38: ='Plastics CCUS_ROCM'!Q38 -> 1.2358653 | V38: =$E38*I$2/1000000 -> 12.858448 | W38: =$E38*J$2/1000000 -> 12.012497 | X38: =$E38*K$2/1000000 -> 18.103341 | Y38: =$E38*L$2/1000000 -> 1.1843307 | Z38: =$E38*M$2/1000000 -> 1.1843307 | AA38: =$E38*P$2/1000000 -> 2.3686614 | AB38: =$E38*R$2/1000000 -> 2.3686614 | AC38: =$E38*S$2/1000000 -> 2.3686614 | AD38: =$E38*V$2/1000000 -> 1.8610911 | AE38: =$E38*W$2/1000000 -> 11.843307 | AF38: =$E38*X$2/1000000 -> 5.9216536 | AG38: =$E38*Y$2/1000000 -> 2.8762317 | AH38: =$E38*Z$2/1000000 -> 30.623408 | AI38: =$E38*AA$2/1000000 -> 20.641192 | AJ38: =$E38*AB$2/1000000 -> 19.626052 | AK38: =$E38*AC$2/1000000 -> 23.348234 | AL38: =SUM(V38:AK38) -> 169.1901 | AM38: =$E38*AE$2 -> 6772444.7 | AN38: =$E38*AF$2/1000000 -> 191.79563 | AO38: =$E38*AG$2/(42*1000) -> 485.59842 | AP38: =$E38*AH$2/1000 -> 77.203943 | AQ38: =$E38*AI$2/1000000 -> 323.33249
A39: ='Texas pop'!A135 -> 0 | B39: ='Texas pop'!B135 -> 0 | C39: ='Texas pop'!C135 -> 11036698 | D39: ='Texas pop'!D135 -> 12577990 | E39: ='Texas pop'!E135 -> 12569590 | F39: =E39*$C$46*$D$45/1000000000 -> 174.66336 | G39: =E39/1000*$D$41/0.9/1000 -> 7245.1055 | J39: =$E39*I$2 -> 1.7809113e+08 | K39: =$E39*J$2 -> 1.663746e+08 | M39: =$E39*K$2 -> 2.5073356e+08 | N39: =$E39*L$2 -> 16403130 | O39: =$E39*M$2 -> 16403130 | Q39: =$E39*P$2 -> 32806260 | R39: =$E39*R$2 -> 32806260 | S39: =$E39*S$2 -> 32806260 | V39: =$E39*V$2 -> 25776347 | W39: =$E39*W$2 -> 1.640313e+08 | X39: =$E39*X$2 -> 82015650 | Y39: =$E39*Y$2 -> 39836173 | Z39: =$E39*Z$2 -> 4.2413807e+08 | AA39: =$E39*AA$2 -> 2.8588312e+08 | AB39: =$E39*AB$2 -> 2.718233e+08 | AC39: =$E39*AC$2 -> 3.2337599e+08
A40: ='Texas pop'!A136 -> 0 | B40: ='Texas pop'!B136 -> 13427775 | C40: ='Texas pop'!C136 -> 0 | D40: ='Texas pop'!D136 -> 0 | E40: ='Texas pop'!E136 -> 0 | K40: https://www.eia.gov/dnav/ng/hist/n3035tx3m.htm
B41: 2029 | C41: Emissions (kg/car) | D41: =576.3995*0.9 -> 518.75955 | E41: =E17*D41/1000 -> 115818.29 | K41: https://www.naturalgasintel.com/natural-gas-to-become-worlds-primary-fossil-fuel-by-2050-says-gas-exporting-countries-forum/
C42: ROCM | D42: 4.3 | E42: =E41/7.2 -> 16085.873 | F42: TONS OF ETHYLENE
C43: YIELD | D43: 0.95 | E43: =E42*D43 -> 15281.579 | F43: TONS OF POLYETHYLENE | I43: Table 7. Average Value of Plastics & Polymer Composites ($/vehicle)
B44: KG OF PE/CAR | D44: 8.09 | E44: =E17*D44/1000 -> 1806.1738 | F44: TONS IN 2029 REQ FOR PE | I44: 2021 | J44: 710 | K44: https://plasticmakers.org/wp-content/uploads/2023/02/Chemistry-and-Automobiles-March-2023.pdf
B45: KG OF PLASTIC/CAR | D45: 192.53 | E45: =D45*E18/1000 -> 49861.74 | F45: TONS IN 2029 REQ GENERAL | J45: =J51*J44 -> 1054.7407 | L45: 45717
A46: GREET | B46: Total MJ/kg plastic | C46: 72.174252 | I46: RANGES $15,000 to $25,000 USD | L46: =L45-J44+J45 -> 46061.741 | M46: =L46/L45-1 -> 0.0075407558 | N46: INCREMENT OF 2.84% IN THE CAR PRICE (25000)
D47: IF WHOLE CAR WAS PE, TONS REQ | N47: https://www.wfaa.com/article/money/business/right-on-the-money/as-auto-prices-soar-across-check-your-auto-insurance/287-db5a20d6-5bd7-45c4-a870-d48c8491a352#:~:text=As%20auto%20prices%20soar%20across,costs%20almost%20%2430%2C000%20(%2429%2C969%20).
D48: FROM 2029 I CAN PRODUCE | F48: BY 2030 I NEED | H48: FROM NG I NEED | J48: FINAL PRICE/ TON PLASTIC (NO EMISSIONS)
D49: =E43 -> 15281.579 | F49: =E45 -> 49861.74 | H49: =F49-D49 -> 34580.16
B50: PRICES PER TON | D50: 1764.5099 | H50: 500 | J50: =D49/$F$49*D50+H49/$F$49*H50 -> 887.54581
J51: ='Plastics CCUS_ROCM'!Q13 -> 1.4855503
E52: Technology | F52: Initial cost/BAU (2025) | G52: Initial cost USD/ton (2025) | H52: Impact in car cost | I52: Final cost/BAU (2050) | J52: Final cost USD/ton (2050) | K52: 2.0632836 | L52: 100% CCUS (90% YIELD)
E53: RMTO | F53: ='Plastics CCUS_RMTO'!Q13 -> 1.5329537 | G53: ='Plastics CCUS_ROCM'!M13 -> 1248.9627 | H53: ='Plastics CCUS_RMTO'!M46 -> 0.0082769459 | I53: ='Plastics CCUS_RMTO'!Q38 -> 1.1906606 | J53: ='Plastics CCUS_RMTO'!M38 -> 1190.6606 | K53: 1.8506269 | L53: 80% CCUS (90% YIELD)
...

Sheet Plastics CCUS_RMTO
W1: Natural gas thousand cu ft/car | X1: Natural gas Million (m3)/car | Y1: Crude oil gal/car | Z1: Crude oil Thousands (m3)/car | AA1: Electricity kWh/car | AC1: ng mass
E2: Value/car | I2: 14.168411 | J2: 13.236279 | K2: 19.947632 | L2: 1.3049853 | M2: 1.3049853 | N2: 2.6099705 | P2: 2.6099705 | Q2: 2.6099705 | R2: 2.0506911 | S2: 13.049853 | T2: 6.5249263 | U2: 3.1692499 | V2: 33.74319 | W2: 22.744029 | X2: 21.62547 | Y2: 25.726852 | AA2: 7.4623924 | AB2: =28.32*7.46239236299982 -> 211.33495 | AC2: 22.472903 | AD2: =0.00378541*22.4729025711425 -> 0.08506915 | AE2: 356.27222 | AG2: 2636.4 | AH2: 50000
A3: ='Texas pop'!A99 -> Year | B3: ='Texas pop'!B99 -> Population | C3: ='Texas pop'!C99 -> EVs | D3: ='Texas pop'!D99 -> EVs w retirement | E3: ='Texas pop'!E99 -> Sales Difference/New cars | F3: ENERGY REQUIRED [PJ] | G3: TONS OF CO2 EMITTED | H3: TONS OF CO2 CAPTURED | I3: TONS OF PE PRODUCED THROGH CCUS | J3: "TONS REQ" | K3: DELTA (NG NEEDED) | L3: FINAL PRICE/ TON PLASTIC CONVENTIONAL | M3: FINAL PRICE/ TON PLASTIC NO EMISSIONS | N3: JANUARY NG PRICE BASED (USD/THOUSAND CU FT) | O3: NG PRICE/TON PLASTIC | P3: CCUS PRICE | Q3: RATIO COST NO EMI/EM | R3: ABS | S3: EPDM | T3: LER | U3: GPPS | V3: HIPS | W3: HDPE | X3: LDPE | Y3: LLDPE | Z3: Nylon 6 | AA3: Nylon 66 | AB3: PC | AC3: PET | AD3: PP | AE3: FPUR foam | AF3: RPUR foam | AG3: PVC | AH3: Total | AI3: NG | AJ3: NG | AK3: Crude oil | AM3: Electricity | AO3: =AP3*AG2/AH2 -> 393.47702 | AP3: =7.46239236299982*1000 -> 7462.3924
A4: ='Texas pop'!A100 -> 2016 | B4: ='Texas pop'!B100 -> 27914064 | C4: ='Texas pop'!C100 -> 11900 | D4: ='Texas pop'!D100 -> 11900 | E4: ='Texas pop'!E100 -> 4200 | F4: =E4*$C$46*$D$45/1000000000 -> 0.058361977 | G4: =E4/1000*$D$41/0.9/1000 -> 2.4208779 | H4: 0 | I4: =H4/$D$42*$D$43 -> 0 | J4: =$D$45*E4/1000 -> 808.626 | L4: =O4 -> 453.7037 | M4: =O4 -> 453.7037 | N4: 2.45 | O4: =$H$50/2.7*N4 -> 453.7037 | P4: =P5/D43 -> 1955.1356 | Q4: =M4/L4 -> 1 | R4: =$E4*I$2/1000000 -> 0.059507328 | S4: =$E4*J$2/1000000 -> 0.055592372 | T4: =$E4*K$2/1000000 -> 0.083780053 | U4: =$E4*L$2/1000000 -> 0.0054809381 | V4: =$E4*M$2/1000000 -> 0.0054809381 | W4: =$E4*N$2/1000000 -> 0.010961876 | X4: =$E4*P$2/1000000 -> 0.010961876 | Y4: =$E4*Q$2/1000000 -> 0.010961876 | Z4: =$E4*R$2/1000000 -> 0.0086129027 | AA4: =$E4*S$2/1000000 -> 0.054809381 | AB4: =$E4*T$2/1000000 -> 0.02740469 | AC4: =$E4*U$2/1000000 -> 0.01331085 | AD4: =$E4*V$2/1000000 -> 0.1417214 | AE4: =$E4*W$2/1000000 -> 0.095524921 | ... AG4: =$E4*Y$2/1000000 -> 0.10805278 | AH4: =SUM(R4:AG4) -> 0.78299115 | AI4: =$E4*AA$2 -> 31342.048 | AJ4: =$E4*AB$2/1000000 -> 0.8876068 | AK4: =$E4*AC$2/(42*1000) -> 2.2472903 | AL4: =$E4*AD$2/1000 -> 0.35729043 | AM4: =$E4*AE$2/1000000 -> 1.4963433 | AO4: =AO3*AP5 -> 178.47803 | AP4: kgs
A5: ='Texas pop'!A101 -> 2017 | B5: ='Texas pop'!B101 -> 28291024 | C5: ='Texas pop'!C101 -> 16100 | D5: ='Texas pop'!D101 -> 16100 | E5: ='Texas pop'!E101 -> 8400 | F5: =E5*$C$46*$D$45/1000000000 -> 0.11672395 | G5: =E5/1000*$D$41/0.9/1000 -> 4.8417558 | H5: 0 | I5: =H5/$D$42*$D$43 -> 0 | J5: =$D$45*E5/1000 -> 1617.252 | K5: =J5-I4 -> 1617.252 | L5: =O5 -> 711.11111 | M5: =O5 -> 711.11111 | N5: 3.84 | O5: =$H$50/2.7*N5 -> 711.11111 | P5: =D50/D43 -> 1857.3788 | Q5: =M5/L5 -> 1 | R5: =$E5*I$2/1000000 -> 0.11901466 | S5: =$E5*J$2/1000000 -> 0.11118474 | T5: =$E5*K$2/1000000 -> 0.16756011 | U5: =$E5*L$2/1000000 -> 0.010961876 | V5: =$E5*M$2/1000000 -> 0.010961876 | W5: =$E5*N$2/1000000 -> 0.021923752 | X5: =$E5*P$2/1000000 -> 0.021923752 | Y5: =$E5*Q$2/1000000 -> 0.021923752 | Z5: =$E5*R$2/1000000 -> 0.017225805 | AA5: =$E5*S$2/1000000 -> 0.10961876 | AB5: =$E5*T$2/1000000 -> 0.054809381 | AC5: =$E5*U$2/1000000 -> 0.026621699 | AD5: =$E5*V$2/1000000 -> 0.2834428 | AE5: =$E5*W$2/1000000 -> 0.19104984 | ... AG5: =$E5*Y$2/1000000 -> 0.21610556 | AH5: =SUM(R5:AG5) -> 1.5659823 | AI5: =$E5*AA$2 -> 62684.096 | AJ5: =$E5*AB$2/1000000 -> 1.7752136 | AK5: =$E5*AC$2/(42*1000) -> 4.4945805 | AL5: =$E5*AD$2/1000 -> 0.71458086 | AM5: =$E5*AE$2/1000000 -> 2.9926866 | AO5: lbs to kg | AP5: 0.453592
A6: ='Texas pop'!A102 -> 2018 | B6: ='Texas pop'!B102 -> 28624564 | C6: ='Texas pop'!C102 -> 24500 | D6: ='Texas pop'!D102 -> 24500 | E6: ='Texas pop'!E102 -> 13900 | F6: =E6*$C$46*$D$45/1000000000 -> 0.19315035 | G6: =E6/1000*$D$41/0.9/1000 -> 8.0119531 | H6: 0 | I6: =H6/$D$42*$D$43 -> 0 | J6: =$D$45*E6/1000 -> 2676.167 | K6: =J6-I5 -> 2676.167 | L6: =O6 -> 620.37037 | M6: =O6 -> 620.37037 | N6: 3.35 | O6: =$H$50/2.7*N6 -> 620.37037 | P6: =P5*(1-0.01) -> 1838.805 | Q6: =M6/L6 -> 1 | R6: =$E6*I$2/1000000 -> 0.19694092 | S6: =$E6*J$2/1000000 -> 0.18398428 | T6: =$E6*K$2/1000000 -> 0.27727208 | U6: =$E6*L$2/1000000 -> 0.018139295 | V6: =$E6*M$2/1000000 -> 0.018139295 | W6: =$E6*N$2/1000000 -> 0.03627859 | X6: =$E6*P$2/1000000 -> 0.03627859 | Y6: =$E6*Q$2/1000000 -> 0.03627859 | Z6: =$E6*R$2/1000000 -> 0.028504607 | AA6: =$E6*S$2/1000000 -> 0.18139295 | AB6: =$E6*T$2/1000000 -> 0.090696475 | AC6: =$E6*U$2/1000000 -> 0.044052574 | AD6: =$E6*V$2/1000000 -> 0.46903034 | AE6: =$E6*W$2/1000000 -> 0.316142 | ... AG6: =$E6*Y$2/1000000 -> 0.35760325 | AH6: =SUM(R6:AG6) -> 2.5913279 | AI6: =$E6*AA$2 -> 103727.25 | AJ6: =$E6*AB$2/1000000 -> 2.9375558 | AK6: =$E6*AC$2/(42*1000) -> 7.4374606 | AL6: =$E6*AD$2/1000 -> 1.1824612 | AM6: =$E6*AE$2/1000000 -> 4.9521838
A7: ='Texas pop'!A103 -> 2019 | B7: ='Texas pop'!B103 -> 28986794 | C7: ='Texas pop'!C103 -> 38400 | D7: ='Texas pop'!D103 -> 38400 | E7: ='Texas pop'!E103 -> 13800 | F7: =E7*$C$46*$D$45/1000000000 -> 0.19176078 | G7: =E7/1000*$D$41/0.9/1000 -> 7.9543131 | H7: 0 | I7: =H7/$D$42*$D$43 -> 0 | J7: =$D$45*E7/1000 -> 2656.914 | K7: =J7-I6 -> 2656.914 | L7: =O7 -> 725.92593 | M7: =O7 -> 725.92593 | N7: 3.92 | O7: =$H$50/2.7*N7 -> 725.92593 | P7: =P6*(1-0.01) -> 1820.417 | Q7: =M7/L7 -> 1 | R7: =$E7*I$2/1000000 -> 0.19552408 | S7: =$E7*J$2/1000000 -> 0.18266065 | T7: =$E7*K$2/1000000 -> 0.27527732 | U7: =$E7*L$2/1000000 -> 0.018008797 | V7: =$E7*M$2/1000000 -> 0.018008797 | W7: =$E7*N$2/1000000 -> 0.036017593 | X7: =$E7*P$2/1000000 -> 0.036017593 | Y7: =$E7*Q$2/1000000 -> 0.036017593 | Z7: =$E7*R$2/1000000 -> 0.028299537 | AA7: =$E7*S$2/1000000 -> 0.18008797 | AB7: =$E7*T$2/1000000 -> 0.090043983 | AC7: =$E7*U$2/1000000 -> 0.043735649 | AD7: =$E7*V$2/1000000 -> 0.46565602 | AE7: =$E7*W$2/1000000 -> 0.3138676 | ... AG7: =$E7*Y$2/1000000 -> 0.35503056 | AH7: =SUM(R7:AG7) -> 2.5726852 | AI7: =$E7*AA$2 -> 102981.01 | AJ7: =$E7*AB$2/1000000 -> 2.9164223 | AK7: =$E7*AC$2/(42*1000) -> 7.3839537 | AL7: =$E7*AD$2/1000 -> 1.1739543 | AM7: =$E7*AE$2/1000000 -> 4.9165566 | AO7: oil mass
A8: ='Texas pop'!A104 -> 2020 | B8: ='Texas pop'!B104 -> 29232474 | C8: ='Texas pop'!C104 -> 52200 | D8: ='Texas pop'!D104 -> 52200 | E8: ='Texas pop'!E104 -> 28700 | F8: =E8*$C$46*$D$45/1000000000 -> 0.39880684 | G8: =E8/1000*$D$41/0.9/1000 -> 16.542666 | H8: 0 | I8: =H8/$D$42*$D$43 -> 0 | J8: =$D$45*E8/1000 -> 5525.611 | K8: =J8-I7 -> 5525.611 | L8: =O8 -> 429.62963 | M8: =O8 -> 429.62963 | N8: 2.32 | O8: =$H$50/2.7*N8 -> 429.62963 | P8: =P7*(1-0.01) -> 1802.2128 | Q8: =M8/L8 -> 1 | R8: =$E8*I$2/1000000 -> 0.40663341 | S8: =$E8*J$2/1000000 -> 0.37988121 | T8: =$E8*K$2/1000000 -> 0.57249703 | U8: =$E8*L$2/1000000 -> 0.037453077 | V8: =$E8*M$2/1000000 -> 0.037453077 | W8: =$E8*N$2/1000000 -> 0.074906154 | X8: =$E8*P$2/1000000 -> 0.074906154 | Y8: =$E8*Q$2/1000000 -> 0.074906154 | Z8: =$E8*R$2/1000000 -> 0.058854835 | AA8: =$E8*S$2/1000000 -> 0.37453077 | AB8: =$E8*T$2/1000000 -> 0.18726538 | AC8: =$E8*U$2/1000000 -> 0.090957472 | AD8: =$E8*V$2/1000000 -> 0.96842956 | AE8: =$E8*W$2/1000000 -> 0.65275362 | ... AG8: =$E8*Y$2/1000000 -> 0.73836066 | AH8: =SUM(R8:AG8) -> 5.3504395 | AI8: =$E8*AA$2 -> 214170.66 | AJ8: =$E8*AB$2/1000000 -> 6.0653131 | AK8: =$E8*AC$2/(42*1000) -> 15.356483 | AL8: =$E8*AD$2/1000 -> 2.4414846 | AM8: =$E8*AE$2/1000000 -> 10.225013 | AO8: 7.2 | AP8: =AO8*AC2 -> 161.8049
A9: ='Texas pop'!A105 -> 2021 | B9: ='Texas pop'!B105 -> 29558864 | C9: ='Texas pop'!C105 -> 80900 | D9: ='Texas pop'!D105 -> 80900 | E9: ='Texas pop'!E105 -> 68100 | F9: =E9*$C$46*$D$45/1000000000 -> 0.94629776 | G9: =E9/1000*$D$41/0.9/1000 -> 39.252806 | H9: 0 | I9: =H9/$D$42*$D$43 -> 0 | J9: =$D$45*E9/1000 -> 13111.293 | K9: =J9-I8 -> 13111.293 | L9: =O9 -> 511.11111 | M9: =O9 -> 511.11111 | N9: 2.76 | O9: =$H$50/2.7*N9 -> 511.11111 | P9: =P8*(1-0.01) -> 1784.1907 | Q9: =M9/L9 -> 1 | R9: =$E9*I$2/1000000 -> 0.96486881 | S9: =$E9*J$2/1000000 -> 0.9013906 | T9: =$E9*K$2/1000000 -> 1.3584337 | U9: =$E9*L$2/1000000 -> 0.088869496 | V9: =$E9*M$2/1000000 -> 0.088869496 | W9: =$E9*N$2/1000000 -> 0.17773899 | X9: =$E9*P$2/1000000 -> 0.17773899 | Y9: =$E9*Q$2/1000000 -> 0.17773899 | Z9: =$E9*R$2/1000000 -> 0.13965206 | AA9: =$E9*S$2/1000000 -> 0.88869496 | AB9: =$E9*T$2/1000000 -> 0.44434748 | AC9: =$E9*U$2/1000000 -> 0.21582592 | AD9: =$E9*V$2/1000000 -> 2.2979113 | AE9: =$E9*W$2/1000000 -> 1.5488684 | ... AG9: =$E9*Y$2/1000000 -> 1.7519986 | AH9: =SUM(R9:AG9) -> 12.695642 | AI9: =$E9*AA$2 -> 508188.92 | AJ9: =$E9*AB$2/1000000 -> 14.39191 | AK9: =$E9*AC$2/(42*1000) -> 36.438206 | AL9: =$E9*AD$2/1000 -> 5.7932091 | AM9: =$E9*AE$2/1000000 -> 24.262138 | AO9: kgs | AP9: =AP5*AP8 -> 73.393408
A10: ='Texas pop'!A106 -> 2022 | B10: ='Texas pop'!B106 -> 30029572 | C10: ='Texas pop'!C106 -> 149000 | D10: ='Texas pop'!D106 -> 149000 | E10: ='Texas pop'!E106 -> 78996 | F10: =E10*$C$46*$D$45/1000000000 -> 1.0977054 | G10: =E10/1000*$D$41/0.9/1000 -> 45.533255 | H10: 0 | I10: =H10/$D$42*$D$43 -> 0 | J10: =$D$45*E10/1000 -> 15209.1 | K10: =J10-I9 -> 15209.1 | L10: =O10 -> 901.85185 | M10: =O10 -> 901.85185 | N10: 4.87 | O10: =$H$50/2.7*N10 -> 901.85185 | P10: =P9*(1-0.01) -> 1766.3488 | Q10: =M10/L10 -> 1 | R10: =$E10*I$2/1000000 -> 1.1192478 | S10: =$E10*J$2/1000000 -> 1.0456131 | T10: =$E10*K$2/1000000 -> 1.5757831 | U10: =$E10*L$2/1000000 -> 0.10308862 | V10: =$E10*M$2/1000000 -> 0.10308862 | W10: =$E10*N$2/1000000 -> 0.20617723 | X10: =$E10*P$2/1000000 -> 0.20617723 | Y10: =$E10*Q$2/1000000 -> 0.20617723 | Z10: =$E10*R$2/1000000 -> 0.1619964 | AA10: =$E10*S$2/1000000 -> 1.0308862 | AB10: =$E10*T$2/1000000 -> 0.51544308 | AC10: =$E10*U$2/1000000 -> 0.25035807 | AD10: =$E10*V$2/1000000 -> 2.6655771 | AE10: =$E10*W$2/1000000 -> 1.7966873 | ... AG10: =$E10*Y$2/1000000 -> 2.0323184 | AH10: =SUM(R10:AG10) -> 14.726945 | AI10: =$E10*AA$2 -> 589499.15 | AJ10: =$E10*AB$2/1000000 -> 16.694616 | AK10: =$E10*AC$2/(42*1000) -> 42.268319 | AL10: =$E10*AD$2/1000 -> 6.7201226 | AM10: =$E10*AE$2/1000000 -> 28.14408 | AO10: kgs | AP10: =AO4+AP9 -> 251.87144
A11: ='Texas pop'!A107 -> 2023 | B11: ='Texas pop'!B107 -> 30303924 | C11: ='Texas pop'!C107 -> 227996 | D11: ='Texas pop'!D107 -> 227996 | E11: ='Texas pop'!E107 -> 91635.36 | F11: =E11*$C$46*$D$45/1000000000 -> 1.2733383 | G11: =E11/1000*$D$41/0.9/1000 -> 52.818576 | H11: 0 | I11: =H11/$D$42*$D$43 -> 0 | J11: =$D$45*E11/1000 -> 17642.556 | K11: =J11-I10 -> 17642.556 | L11: =O11 -> 831.48148 | M11: =O11 -> 831.48148 | N11: 4.49 | O11: =$H$50/2.7*N11 -> 831.48148 | P11: =P10*(1-0.01) -> 1748.6853 | Q11: =M11/L11 -> 1 | R11: =$E11*I$2/1000000 -> 1.2983275 | S11: =$E11*J$2/1000000 -> 1.2129112 | T11: =$E11*K$2/1000000 -> 1.8279084 | U11: =$E11*L$2/1000000 -> 0.11958279 | V11: =$E11*M$2/1000000 -> 0.11958279 | W11: =$E11*N$2/1000000 -> 0.23916559 | X11: =$E11*P$2/1000000 -> 0.23916559 | Y11: =$E11*Q$2/1000000 -> 0.23916559 | Z11: =$E11*R$2/1000000 -> 0.18791582 | AA11: =$E11*S$2/1000000 -> 1.1958279 | AB11: =$E11*T$2/1000000 -> 0.59791397 | AC11: =$E11*U$2/1000000 -> 0.29041536 | AD11: =$E11*V$2/1000000 -> 3.0920694 | AE11: =$E11*W$2/1000000 -> 2.0841573 | ... AG11: =$E11*Y$2/1000000 -> 2.3574894 | AH11: =SUM(R11:AG11) -> 17.083256 | AI11: =$E11*AA$2 -> 683819.01 | AJ11: =$E11*AB$2/1000000 -> 19.365754 | AK11: =$E11*AC$2/(42*1000) -> 49.03125 | AL11: =$E11*AD$2/1000 -> 7.7953422 | AM11: =$E11*AE$2/1000000 -> 32.647133 | AO11: final | AP11: 186.43
A12: ='Texas pop'!A108 -> 2024 | B12: ='Texas pop'!B108 -> 30642857 | C12: ='Texas pop'!C108 -> 319631.36 | D12: ='Texas pop'!D108 -> 319631.36 | E12: ='Texas pop'!E108 -> 106297.02 | F12: =E12*$C$46*$D$45/1000000000 -> 1.4770724 | G12: =E12/1000*$D$41/0.9/1000 -> 61.269548 | H12: =E12*$D$41/1000 -> 55142.593 | I12: =H12/$D$42*$D$43 -> 12182.666 | J12: =$D$45*E12/1000 -> 20465.365 | K12: =J12-I11 -> 20465.365 | L12: =O12 -> 833.33333 | M12: =I11/J12*P12+K12/J12*O12 -> 833.33333 | N12: 4.5 | O12: =$H$50/2.7*N12 -> 833.33333 | P12: =P11*(1-0.01) -> 1731.1984 | Q12: =M12/L12 -> 1 | R12: =$E12*I$2/1000000 -> 1.5060599 | S12: =$E12*J$2/1000000 -> 1.406977 | T12: =$E12*K$2/1000000 -> 2.1203738 | U12: =$E12*L$2/1000000 -> 0.13871604 | V12: =$E12*M$2/1000000 -> 0.13871604 | W12: =$E12*N$2/1000000 -> 0.27743208 | X12: =$E12*P$2/1000000 -> 0.27743208 | Y12: =$E12*Q$2/1000000 -> 0.27743208 | Z12: =$E12*R$2/1000000 -> 0.21798235 | AA12: =$E12*S$2/1000000 -> 1.3871604 | AB12: =$E12*T$2/1000000 -> 0.6935802 | AC12: =$E12*U$2/1000000 -> 0.33688181 | AD12: =$E12*V$2/1000000 -> 3.5868005 | AE12: =$E12*W$2/1000000 -> 2.4176224 | ... AG12: =$E12*Y$2/1000000 -> 2.7346877 | AH12: =SUM(R12:AG12) -> 19.816577 | AI12: =$E12*AA$2 -> 793230.05 | AJ12: =$E12*AB$2/1000000 -> 22.464275 | AK12: =$E12*AC$2/(42*1000) -> 56.87625 | AL12: =$E12*AD$2/1000 -> 9.0425969 | AM12: =$E12*AE$2/1000000 -> 37.870674 | AO12: Mass req/kg output | AP12: =AP10/AP11 -> 1.3510242
A13: ='Texas pop'!A109 -> 2025 | B13: ='Texas pop'!B109 -> 30981790 | C13: ='Texas pop'!C109 -> 425928.38 | D13: ='Texas pop'!D109 -> 425928.38 | E13: ='Texas pop'!E109 -> 123304.54 | F13: =E13*$C$46*$D$45/1000000000 -> 1.713404 | G13: =E13/1000*$D$41/0.9/1000 -> 71.072675 | H13: =E13*$D$41/1000 -> 63965.408 | I13: =H13/$D$42*$D$43 -> 14131.892 | J13: =$D$45*E13/1000 -> 23739.823 | K13: =J13-I12 -> 11557.157 | L13: =O13 -> 840.74074 | M13: =I12/J13*P13+K13/J13*O13 -> 1288.8166 | N13: 4.54 | O13: =$H$50/2.7*N13 -> 840.74074 | P13: =P12*(1-0.01) -> 1713.8865 | Q13: =M13/L13 -> 1.5329537 | R13: =$E13*I$2/1000000 -> 1.7470294 | S13: =$E13*J$2/1000000 -> 1.6320933 | T13: =$E13*K$2/1000000 -> 2.4596336 | U13: =$E13*L$2/1000000 -> 0.16091061 | V13: =$E13*M$2/1000000 -> 0.16091061 | W13: =$E13*N$2/1000000 -> 0.32182121 | X13: =$E13*P$2/1000000 -> 0.32182121 | Y13: =$E13*Q$2/1000000 -> 0.32182121 | Z13: =$E13*R$2/1000000 -> 0.25285953 | AA13: =$E13*S$2/1000000 -> 1.6091061 | AB13: =$E13*T$2/1000000 -> 0.80455304 | AC13: =$E13*U$2/1000000 -> 0.3907829 | AD13: =$E13*V$2/1000000 -> 4.1606886 | AE13: =$E13*W$2/1000000 -> 2.804442 | ... AG13: =$E13*Y$2/1000000 -> 3.1722377 | AH13: =SUM(R13:AG13) -> 22.98723 | AI13: =$E13*AA$2 -> 920146.86 | AJ13: =$E13*AB$2/1000000 -> 26.058559 | AK13: =$E13*AC$2/(42*1000) -> 65.976451 | AL13: =$E13*AD$2/1000 -> 10.489412 | AM13: =$E13*AE$2/1000000 -> 43.929982
A14: ='Texas pop'!A110 -> 2026 | B14: ='Texas pop'!B110 -> 31320722 | C14: ='Texas pop'!C110 -> 549232.92 | D14: ='Texas pop'!D110 -> 549232.92 | E14: ='Texas pop'!E110 -> 143033.27 | F14: =E14*$C$46*$D$45/1000000000 -> 1.9875486 | G14: =E14/1000*$D$41/0.9/1000 -> 82.444304 | H14: =E14*$D$41/1000 -> 74199.873 | I14: =H14/$D$42*$D$43 -> 16392.995 | J14: =$D$45*E14/1000 -> 27538.195 | K14: =J14-I13 -> 13406.302 | L14: =O14 -> 848.14815 | M14: =I13/J14*P14+K14/J14*O14 -> 1283.6275 | N14: 4.58 | O14: =$H$50/2.7*N14 -> 848.14815 | P14: =P13*(1-0.01) -> 1696.7476 | Q14: =M14/L14 -> 1.5134473 | R14: =$E14*I$2/1000000 -> 2.0265542 | S14: =$E14*J$2/1000000 -> 1.8932282 | T14: =$E14*K$2/1000000 -> 2.8531749 | U14: =$E14*L$2/1000000 -> 0.1866563 | V14: =$E14*M$2/1000000 -> 0.1866563 | W14: =$E14*N$2/1000000 -> 0.37331261 | X14: =$E14*P$2/1000000 -> 0.37331261 | Y14: =$E14*Q$2/1000000 -> 0.37331261 | Z14: =$E14*R$2/1000000 -> 0.29331705 | AA14: =$E14*S$2/1000000 -> 1.866563 | AB14: =$E14*T$2/1000000 -> 0.93328152 | AC14: =$E14*U$2/1000000 -> 0.45330817 | AD14: =$E14*V$2/1000000 -> 4.8263987 | AE14: =$E14*W$2/1000000 -> 3.2531527 | ... AG14: =$E14*Y$2/1000000 -> 3.6797957 | AH14: =SUM(R14:AG14) -> 26.665186 | AI14: =$E14*AA$2 -> 1067370.4 | AJ14: =$E14*AB$2/1000000 -> 30.227929 | AK14: =$E14*AC$2/(42*1000) -> 76.532683 | AL14: =$E14*AD$2/1000 -> 12.167718 | AM14: =$E14*AE$2/1000000 -> 50.958779
A15: ='Texas pop'!A111 -> 2027 | B15: ='Texas pop'!B111 -> 31659655 | C15: ='Texas pop'!C111 -> 692266.18 | D15: ='Texas pop'!D111 -> 692266.18 | E15: ='Texas pop'!E111 -> 165918.59 | F15: =E15*$C$46*$D$45/1000000000 -> 2.3055564 | G15: =E15/1000*$D$41/0.9/1000 -> 95.635392 | H15: =E15*$D$41/1000 -> 86071.853 | I15: =H15/$D$42*$D$43 -> 19015.874 | J15: =$D$45*E15/1000 -> 31944.306 | K15: =J15-I14 -> 15551.311 | L15: =O15 -> 888.88889 | M15: =I14/J15*P15+K15/J15*O15 -> 1294.7539 | N15: 4.8 | O15: =$H$50/2.7*N15 -> 888.88889 | P15: =P14*(1-0.01) -> 1679.7801 | Q15: =M15/L15 -> 1.4565981 | R15: =$E15*I$2/1000000 -> 2.3508028 | S15: =$E15*J$2/1000000 -> 2.1961447 | T15: =$E15*K$2/1000000 -> 3.3096829 | U15: =$E15*L$2/1000000 -> 0.21652131 | V15: =$E15*M$2/1000000 -> 0.21652131 | W15: =$E15*N$2/1000000 -> 0.43304263 | X15: =$E15*P$2/1000000 -> 0.43304263 | Y15: =$E15*Q$2/1000000 -> 0.43304263 | Z15: =$E15*R$2/1000000 -> 0.34024778 | AA15: =$E15*S$2/1000000 -> 2.1652131 | AB15: =$E15*T$2/1000000 -> 1.0826066 | AC15: =$E15*U$2/1000000 -> 0.52583747 | AD15: =$E15*V$2/1000000 -> 5.5986225 | AE15: =$E15*W$2/1000000 -> 3.7736572 | ... AG15: =$E15*Y$2/1000000 -> 4.268563 | AH15: =SUM(R15:AG15) -> 30.931616 | AI15: =$E15*AA$2 -> 1238149.6 | AJ15: =$E15*AB$2/1000000 -> 35.064397 | AK15: =$E15*AC$2/(42*1000) -> 88.777912 | AL15: =$E15*AD$2/1000 -> 14.114553 | AM15: =$E15*AE$2/1000000 -> 59.112183
A16: ='Texas pop'!A112 -> 2028 | B16: ='Texas pop'!B112 -> 31998588 | C16: ='Texas pop'!C112 -> 858184.77 | D16: ='Texas pop'!D112 -> 858184.77 | E16: ='Texas pop'!E112 -> 192465.56 | F16: =E16*$C$46*$D$45/1000000000 -> 2.6744454 | G16: =E16/1000*$D$41/0.9/1000 -> 110.93705 | H16: =E16*$D$41/1000 -> 99843.349 | I16: =H16/$D$42*$D$43 -> 22058.414 | J16: =$D$45*E16/1000 -> 37055.395 | K16: =J16-I15 -> 18039.521 | L16: =O16 -> 907.40741 | M16: =I15/J16*P16+K16/J16*O16 -> 1295.149 | N16: 4.9 | O16: =$H$50/2.7*N16 -> 907.40741 | P16: =P15*(1-0.01) -> 1662.9823 | Q16: =M16/L16 -> 1.4273071 | R16: =$E16*I$2/1000000 -> 2.7269313 | S16: =$E16*J$2/1000000 -> 2.5475279 | T16: =$E16*K$2/1000000 -> 3.8392322 | U16: =$E16*L$2/1000000 -> 0.25116472 | V16: =$E16*M$2/1000000 -> 0.25116472 | W16: =$E16*N$2/1000000 -> 0.50232945 | X16: =$E16*P$2/1000000 -> 0.50232945 | Y16: =$E16*Q$2/1000000 -> 0.50232945 | Z16: =$E16*R$2/1000000 -> 0.39468742 | AA16: =$E16*S$2/1000000 -> 2.5116472 | AB16: =$E16*T$2/1000000 -> 1.2558236 | AC16: =$E16*U$2/1000000 -> 0.60997147 | AD16: =$E16*V$2/1000000 -> 6.4944021 | AE16: =$E16*W$2/1000000 -> 4.3774423 | ... AG16: =$E16*Y$2/1000000 -> 4.9515331 | AH16: =SUM(R16:AG16) -> 35.880675 | AI16: =$E16*AA$2 -> 1436253.6 | AJ16: =$E16*AB$2/1000000 -> 40.674701 | AK16: =$E16*AC$2/(42*1000) -> 102.98238 | AL16: =$E16*AD$2/1000 -> 16.372882 | AM16: =$E16*AE$2/1000000 -> 68.570133
